Workbook

Sheet Guide
A1: SONCHOY 360°: Personal Finance Command Center
A2: Version 1.0 - all amounts in BDT (Bangladeshi Taka, with lakh/crore digit grouping) - works in Microsoft Excel and Google Sheets
A4: WHAT IS SONCHOY?
A5: Name | B5: Sonchoy (সঞ্চয়) means 'savings' in Bangla. This workbook is a complete personal finance system built around how money actually works in Bangladesh: bKash/Nagad payments, lakh/crore numbers, DPS/FDR/Sanchayapatra, Eid bonuses and Qurbani, Zakat, NBR income-tax slabs, and loan EMIs.
A7: QUICK START (about 5 minutes)
A8: Step 1 - Settings | B8: Open Settings. Enter your name, tracking year and targets (savings rate, emergency-fund months, max debt-to-income). Review the tax slabs and exchange rates.
A9: Step 2 - Clear sample data | B9: The file ships with SAMPLE data (a fictional Dhaka salaried household, Jan-Oct 2026). In Transactions select the blue cells in rows 6 onward and press Delete. Also overwrite the sample rows in Savings Goals, Debt & Loans, Investments, Net Worth, Bills and Festivals.
A10: Step 3 - Set your budget | B10: Open Budget and type a planned monthly amount (blue) next to every category. Set 'Planned Monthly Income' underneath.
A11: Step 4 - Log transactions | B11: In Transactions add one row per payment or receipt: Date, Type (Income/Expense), Category (dropdown), Description, Payment Method, Amount in BDT. Everything else is automatic.
A12: Step 5 - Read the Dashboard | B12: Pick a month at the top of the Dashboard. KPI cards, the health scorecard, the budget status and all charts refresh automatically.
A13: Step 6 - Monthly routine | B13: At month-end: pay down priority goals, update Net Worth values and record the closing Net Worth in the history table, update Bills due dates.
A14: Google Sheets | B14: Upload the .xlsx to Google Drive and open with Google Sheets (File > Save as Google Sheets). Dropdowns, formulas, conditional formats and charts carry over; the lakh/crore format may show Western commas in Sheets.
A16: SHEET DIRECTORY (click a name to jump)
A17: Guide | B17: This page.
A18: Dashboard | B18: Headline KPIs, financial-health scorecard, top outflows and four charts. Pick the month here.
A19: Transactions | B19: The only place you must type daily: every income and expense (2,000-row capacity).
A20: Budget | B20: Monthly budget vs actual per category, status flags, YTD view and the 50/30/20 rule check.
A21: Annual Matrix | B21: Automatic category x month table for the whole year with annual budget variance.
A22: Monthly Summary | B22: Income, spending, net savings, savings rate and cumulative savings for each month.
A23: Savings Goals | B23: Hajj, education, flat, emergency fund and more: required monthly saving, projected value, on-track status.
A24: Debt & Loans | B24: EMI, outstanding balance, interest cost, payoff date, avalanche priority and debt-to-income check.
A25: Investments | B25: DPS, FDR and Sanchayapatra maturity, source tax, net and real (inflation-adjusted) returns.
A26: Net Worth | B26: Assets (incl. gold by bhori) minus liabilities, emergency-fund coverage and net-worth history chart.
A27: Income Tax | B27: NBR slab-based individual tax estimator with exempt salary, investment rebate and minimum tax.
A28: Zakat | B28: Nisab-based Zakat calculator (silver or gold basis) pulling balances from Net Worth.
... A32: Settings | B32: All dropdown lists, categories, tax parameters, FX rates and fee tables. Rename a category once and it updates everywhere.
A34: COLOUR CODE
A35: 1,25,000 | B35: Blue text on pale yellow = INPUT cell. Type here (amounts, dates, rates, assumptions).
A36: =1+1 -> 2 | B36: Black text = FORMULA on the same sheet. Do not overwrite.
A37: =Settings!$B$5 -> 2026 | B37: Green text = value LINKED from another sheet. Do not overwrite.
A38: OVER | B38: Red = over budget / below target / warning. Amber = watch. Green fill = healthy / on track.
A39: TOTAL | B39: Pale green band = totals and key results. Dark bands = section headers.
A41: BANGLADESH-SPECIFIC FEATURES
A42: Feature 1 | B42: Lakh / crore digit grouping (12,34,567) on all BDT amounts; Quick Tools converts BDT to lakh / crore / million.
A43: Feature 2 | B43: Category set built for local life: DESCO / DPDC / REB electricity, Titas gas, WASA, broadband, Rickshaw / CNG / Pathao, bazar, maid, holding tax, Zakat & Fitra, Qurbani, Eid / Boishakh / Puja.
A44: Feature 3 | B44: bKash, Nagad, Rocket, Upay, BEFTN, cheque and auto-debit payment methods; MFS cash-out fee calculator.
A45: Feature 4 | B45: DPS, FDR and Sanchayapatra maturity with source tax (10% with TIN) and real yield after inflation.
A46: Feature 5 | B46: NBR individual income-tax slabs with category thresholds (general, women/senior, disabled, freedom fighter), minimum tax and investment rebate.
A47: Feature 6 | B47: Eid bonus income category, Eid-ul-Fitr / Eid-ul-Adha / Boishakh / Puja planner, Fitra and Qurbani-share calculators.
A48: Feature 7 | B48: Zakat on cash, gold (bhori / tola), silver, shares and savings with silver or gold nisab.
...

Sheet Dashboard
B1: SONCHOY 360°: Personal Finance Command Center
B2: ="Prepared for "&Settings!$B$4&" | Tracking year "&Settings!$B$5&" | All amounts in BDT (Bangladeshi Taka)" -> Prepared for Your Name | Tracking year 2026 | All amounts in BDT (Bangladeshi Taka)
B4: VIEW MONTH > | D4: February | G4: Pick any month - KPIs, budget status and the breakdown charts update instantly.
B6: MONTH INCOME (BDT) | D6: MONTH SPENDING (BDT) | F6: MONTH NET SAVINGS (BDT) | H6: MONTH SAVINGS RATE | J6: YEAR-TO-DATE SAVINGS (BDT) | L6: NET WORTH (BDT)
B7: =INDEX('Monthly Summary'!$B$5:$B$16,Settings!$B$11) -> 128330 | D7: =INDEX('Monthly Summary'!$E$5:$E$16,Settings!$B$11) -> 94240 | F7: =INDEX('Monthly Summary'!$F$5:$F$16,Settings!$B$11) -> 34090 | H7: =INDEX('Monthly Summary'!$G$5:$G$16,Settings!$B$11) -> 0.26564326 | J7: ='Monthly Summary'!$F$17 -> 468924 | L7: ='Net Worth'!$C$25 -> 2100008
B8: =$D$4&" "&Settings!$B$5 -> February 2026 | D8: Excludes savings & investments | F8: Income - Spending | H8: ="Target "&TEXT(Settings!$B$7,"0%") -> Target 20% | J8: Jan to latest month | L8: Assets - Liabilities
B10: BUDGET USED (MONTH) | D10: EMERGENCY FUND (MONTHS) | F10: DEBT-TO-INCOME | H10: AVG MONTHLY INCOME (BDT) | J10: AVG MONTHLY SPENDING (BDT) | L10: SAVINGS GOALS PROGRESS
B11: =Budget!$G$47 -> 0.96243999 | D11: ='Net Worth'!$C$27 -> 2.8618897 | F11: ='Debt & Loans'!$C$21 -> 0.12884348 | H11: ='Monthly Summary'!$B$19 -> 140187.4 | J11: ='Monthly Summary'!$E$19 -> 93295 | L11: ='Savings Goals'!$I$18 -> 0.14641211
B12: All outflows vs total budget | D12: ="Target "&Settings!$B$8&" months" -> Target 6 months | F12: ="Max "&TEXT(Settings!$B$9,"0%") -> Max 40% | H12: Months with income | J12: Months with income | L12: Across all goals
B14: FINANCIAL HEALTH SCORECARD | H14: TOP 5 OUTFLOWS THIS MONTH
B15: Check | D15: Your Value | E15: Target | F15: Status | H15: Category | K15: Amount (BDT) | M15: % of Total
B16: Savings rate (YTD) | D16: ='Monthly Summary'!$G$17 -> 0.33449796 | E16: =Settings!$B$7 -> 0.2 | F16: =IF(D16>=E16,"GOOD",IF(D16>=E16*0.6,"IMPROVE","WARNING")) -> GOOD | H16: =IFERROR(IF(LARGE(Budget!$M$6:$M$46,1)<1,"-",INDEX(Budget!$A$6:$A$46,MATCH(LARGE(Budget!$M$6:$M$46,1),Budget!$M$6:$M$46,0))),"-") -> House Rent | K16: =IFERROR(IF(LARGE(Budget!$M$6:$M$46,1)<1,0,INDEX(Budget!$E$6:$E$46,MATCH(LARGE(Budget!$M$6:$M$46,1),Budget!$M$6:$M$46,0))),0) -> 22000 | M16: =IF(Budget!$E$47=0,0,K16/Budget!$E$47) -> 0.21517997
B17: Emergency fund (months) | D17: ='Net Worth'!$C$27 -> 2.8618897 | E17: =Settings!$B$8 -> 6 | F17: =IF(D17>=E17,"GOOD",IF(D17>=E17/2,"IMPROVE","WARNING")) -> WARNING | H17: =IFERROR(IF(LARGE(Budget!$M$6:$M$46,2)<1,"-",INDEX(Budget!$A$6:$A$46,MATCH(LARGE(Budget!$M$6:$M$46,2),Budget!$M$6:$M$46,0))),"-") -> Loan EMI | K17: =IFERROR(IF(LARGE(Budget!$M$6:$M$46,2)<1,0,INDEX(Budget!$E$6:$E$46,MATCH(LARGE(Budget!$M$6:$M$46,2),Budget!$M$6:$M$46,0))),0) -> 15300 | M17: =IF(Budget!$E$47=0,0,K17/Budget!$E$47) -> 0.14964789
B18: Debt-to-income ratio | D18: ='Debt & Loans'!$C$21 -> 0.12884348 | E18: =Settings!$B$9 -> 0.4 | F18: =IF(D18<=E18,"GOOD",IF(D18<=E18*1.25,"IMPROVE","WARNING")) -> GOOD | H18: =IFERROR(IF(LARGE(Budget!$M$6:$M$46,3)<1,"-",INDEX(Budget!$A$6:$A$46,MATCH(LARGE(Budget!$M$6:$M$46,3),Budget!$M$6:$M$46,0))),"-") -> Travel & Holidays | K18: =IFERROR(IF(LARGE(Budget!$M$6:$M$46,3)<1,0,INDEX(Budget!$E$6:$E$46,MATCH(LARGE(Budget!$M$6:$M$46,3),Budget!$M$6:$M$46,0))),0) -> 12000 | M18: =IF(Budget!$E$47=0,0,K18/Budget!$E$47) -> 0.11737089
B19: Needs share of income (month) | D19: =Budget!$D$59 -> 0.6049248 | E19: =Settings!$B$12 -> 0.5 | F19: =IF(D19<=E19,"GOOD",IF(D19<=E19+0.1,"IMPROVE","WARNING")) -> WARNING | H19: =IFERROR(IF(LARGE(Budget!$M$6:$M$46,4)<1,"-",INDEX(Budget!$A$6:$A$46,MATCH(LARGE(Budget!$M$6:$M$46,4),Budget!$M$6:$M$46,0))),"-") -> Groceries & Bazar | K19: =IFERROR(IF(LARGE(Budget!$M$6:$M$46,4)<1,0,INDEX(Budget!$E$6:$E$46,MATCH(LARGE(Budget!$M$6:$M$46,4),Budget!$M$6:$M$46,0))),0) -> 11610 | M19: =IF(Budget!$E$47=0,0,K19/Budget!$E$47) -> 0.11355634
B20: Wants share of income (month) | D20: =Budget!$D$60 -> 0.12943193 | E20: =Settings!$B$13 -> 0.3 | F20: =IF(D20<=E20,"GOOD",IF(D20<=E20+0.1,"IMPROVE","WARNING")) -> GOOD | H20: =IFERROR(IF(LARGE(Budget!$M$6:$M$46,5)<1,"-",INDEX(Budget!$A$6:$A$46,MATCH(LARGE(Budget!$M$6:$M$46,5),Budget!$M$6:$M$46,0))),"-") -> DPS Deposit | K20: =IFERROR(IF(LARGE(Budget!$M$6:$M$46,5)<1,0,INDEX(Budget!$E$6:$E$46,MATCH(LARGE(Budget!$M$6:$M$46,5),Budget!$M$6:$M$46,0))),0) -> 5000 | M20: =IF(Budget!$E$47=0,0,K20/Budget!$E$47) -> 0.048904538
B21: Categories over budget (month) | D21: =COUNTIF(Budget!$H$6:$H$46,"OVER") -> 5 | E21: 0 | F21: =IF(D21=0,"GOOD",IF(D21<=3,"IMPROVE","WARNING")) -> WARNING | H21: Total outflow this month | K21: =Budget!$E$47 -> 102240 | M21: =IF(K21=0,0,1) -> 1
B22: ="Health score: "&COUNTIF(F16:F21,"GOOD")&" of 6 checks are GOOD" -> Health score: 3 of 6 checks are GOOD
B23: TRENDS & BREAKDOWN
M26: CHART DATA (automatic - do not edit)
M27: Expense Group | N27: Budget (BDT) | O27: Actual (BDT)
M28: =Settings!$O$4 -> Housing & Utilities | N28: =SUMIF(Budget!$B$6:$B$46,M28,Budget!$D$6:$D$46) -> 32180 | O28: =SUMIF(Budget!$B$6:$B$46,M28,Budget!$E$6:$E$46) -> 30610
M29: =Settings!$O$5 -> Food | N29: =SUMIF(Budget!$B$6:$B$46,M29,Budget!$D$6:$D$46) -> 13000 | O29: =SUMIF(Budget!$B$6:$B$46,M29,Budget!$E$6:$E$46) -> 12670
M30: =Settings!$O$6 -> Transport | N30: =SUMIF(Budget!$B$6:$B$46,M30,Budget!$D$6:$D$46) -> 5300 | O30: =SUMIF(Budget!$B$6:$B$46,M30,Budget!$E$6:$E$46) -> 3090
M31: =Settings!$O$7 -> Family & Education | N31: =SUMIF(Budget!$B$6:$B$46,M31,Budget!$D$6:$D$46) -> 9500 | O31: =SUMIF(Budget!$B$6:$B$46,M31,Budget!$E$6:$E$46) -> 8500
M32: =Settings!$O$8 -> Health | N32: =SUMIF(Budget!$B$6:$B$46,M32,Budget!$D$6:$D$46) -> 2000 | O32: =SUMIF(Budget!$B$6:$B$46,M32,Budget!$E$6:$E$46) -> 1770
M33: =Settings!$O$9 -> Lifestyle | N33: =SUMIF(Budget!$B$6:$B$46,M33,Budget!$D$6:$D$46) -> 6900 | O33: =SUMIF(Budget!$B$6:$B$46,M33,Budget!$E$6:$E$46) -> 15550
M34: =Settings!$O$10 -> Religious & Social | N34: =SUMIF(Budget!$B$6:$B$46,M34,Budget!$D$6:$D$46) -> 5500 | O34: =SUMIF(Budget!$B$6:$B$46,M34,Budget!$E$6:$E$46) -> 0
M35: =Settings!$O$11 -> Financial Obligations | N35: =SUMIF(Budget!$B$6:$B$46,M35,Budget!$D$6:$D$46) -> 21350 | O35: =SUMIF(Budget!$B$6:$B$46,M35,Budget!$E$6:$E$46) -> 22050
M36: =Settings!$O$12 -> Savings & Investments | N36: =SUMIF(Budget!$B$6:$B$46,M36,Budget!$D$6:$D$46) -> 9500 | O36: =SUMIF(Budget!$B$6:$B$46,M36,Budget!$E$6:$E$46) -> 8000
M37: =Settings!$O$13 -> Other | N37: =SUMIF(Budget!$B$6:$B$46,M37,Budget!$D$6:$D$46) -> 1000 | O37: =SUMIF(Budget!$B$6:$B$46,M37,Budget!$E$6:$E$46) -> 0
B56: Sonchoy is a planning aid, not financial, tax or religious advice. Verify tax, rate and fee assumptions in Settings. Go to the Guide tab for instructions.

Sheet Transactions
A1: TRANSACTION LOG | লেনদেন
A2: Log every taka in or out. Fill only the blue cells; Group, Month, Year and Check are automatic. ROWS BELOW CONTAIN SAMPLE DATA (Jan-Oct 2026): select the blue cells and press Delete to start fresh.
A4: Entries logged: | B4: =COUNT(G6:G2005) -> 300 | D4: Capacity: 2,000 rows. Insert rows inside the table (not below row 2005) to extend.
A5: Date | B5: Type | C5: Category | D5: Description | E5: Payment Method | F5: Paid To / Received From | G5: Amount (BDT) | H5: Group | I5: Month # | J5: Year | K5: Notes | L5: Check
A6: 46023 | B6: Income | C6: Salary | D6: Salary - January | E6: Bank Transfer / BEFTN | F6: Employer Ltd. | G6: 115000 | H6: =IF(C6="","",IFERROR(INDEX(Settings!$L$4:$L$56,MATCH(C6,Settings!$K$4:$K$56,0)),"Unknown")) -> Income | I6: =IF(A6="","",MONTH(A6)) -> 1 | J6: =IF(A6="","",YEAR(A6)) -> 2026 | L6: =IF(OR(B6="",C6=""),"",IF(AND(B6="Income",H6<>"Income"),"Category is not an Income category",IF(AND(B6="Expense",H6="Income"),"Category is an Income category","OK"))) -> OK
A7: 46024 | B7: Expense | C7: Entertainment & Subscriptions | D7: Netflix / Chorki subscription | E7: Credit Card | F7: Streaming | G7: 1100 | H7: =IF(C7="","",IFERROR(INDEX(Settings!$L$4:$L$56,MATCH(C7,Settings!$K$4:$K$56,0)),"Unknown")) -> Lifestyle | I7: =IF(A7="","",MONTH(A7)) -> 1 | J7: =IF(A7="","",YEAR(A7)) -> 2026 | L7: =IF(OR(B7="",C7=""),"",IF(AND(B7="Income",H7<>"Income"),"Category is not an Income category",IF(AND(B7="Expense",H7="Income"),"Category is an Income category","OK"))) -> OK
A8: 46025 | B8: Expense | C8: House Rent | D8: House rent - January | E8: Bank Transfer / BEFTN | F8: Landlord | G8: 22000 | H8: =IF(C8="","",IFERROR(INDEX(Settings!$L$4:$L$56,MATCH(C8,Settings!$K$4:$K$56,0)),"Unknown")) -> Housing & Utilities | I8: =IF(A8="","",MONTH(A8)) -> 1 | J8: =IF(A8="","",YEAR(A8)) -> 2026 | L8: =IF(OR(B8="",C8=""),"",IF(AND(B8="Income",H8<>"Income"),"Category is not an Income category",IF(AND(B8="Expense",H8="Income"),"Category is an Income category","OK"))) -> OK
A9: 46026 | B9: Expense | C9: Groceries & Bazar | D9: Kacha bazar & grocery | E9: Cash | F9: Local bazar | G9: 3520 | H9: =IF(C9="","",IFERROR(INDEX(Settings!$L$4:$L$56,MATCH(C9,Settings!$K$4:$K$56,0)),"Unknown")) -> Food | I9: =IF(A9="","",MONTH(A9)) -> 1 | J9: =IF(A9="","",YEAR(A9)) -> 2026 | L9: =IF(OR(B9="",C9=""),"",IF(AND(B9="Income",H9<>"Income"),"Category is not an Income category",IF(AND(B9="Expense",H9="Income"),"Category is an Income category","OK"))) -> OK
A10: 46027 | B10: Expense | C10: Maid / Domestic Help | D10: Maid salary | E10: Cash | F10: Domestic help | G10: 3000 | H10: =IF(C10="","",IFERROR(INDEX(Settings!$L$4:$L$56,MATCH(C10,Settings!$K$4:$K$56,0)),"Unknown")) -> Housing & Utilities | I10: =IF(A10="","",MONTH(A10)) -> 1 | J10: =IF(A10="","",YEAR(A10)) -> 2026 | L10: =IF(OR(B10="",C10=""),"",IF(AND(B10="Income",H10<>"Income"),"Category is not an Income category",IF(AND(B10="Expense",H10="Income"),"Category is an Income category","OK"))) -> OK
A11: 46027 | B11: Expense | C11: Loan EMI | D11: Loan EMI (personal + motorcycle) | E11: Auto-debit / Standing Order | F11: Bank | G11: 15300 | H11: =IF(C11="","",IFERROR(INDEX(Settings!$L$4:$L$56,MATCH(C11,Settings!$K$4:$K$56,0)),"Unknown")) -> Financial Obligations | I11: =IF(A11="","",MONTH(A11)) -> 1 | J11: =IF(A11="","",YEAR(A11)) -> 2026 | L11: =IF(OR(B11="",C11=""),"",IF(AND(B11="Income",H11<>"Income"),"Category is not an Income category",IF(AND(B11="Expense",H11="Income"),"Category is an Income category","OK"))) -> OK
A12: 46027 | B12: Expense | C12: DPS Deposit | D12: Monthly DPS instalment | E12: Auto-debit / Standing Order | F12: Dutch-Bangla Bank | G12: 5000 | H12: =IF(C12="","",IFERROR(INDEX(Settings!$L$4:$L$56,MATCH(C12,Settings!$K$4:$K$56,0)),"Unknown")) -> Savings & Investments | I12: =IF(A12="","",MONTH(A12)) -> 1 | J12: =IF(A12="","",YEAR(A12)) -> 2026 | L12: =IF(OR(B12="",C12=""),"",IF(AND(B12="Income",H12<>"Income"),"Category is not an Income category",IF(AND(B12="Expense",H12="Income"),"Category is an Income category","OK"))) -> OK
A13: 46027 | B13: Expense | C13: School / College / University Fees | D13: School tuition fee | E13: Bank Transfer / BEFTN | F13: Child's school | G13: 3500 | H13: =IF(C13="","",IFERROR(INDEX(Settings!$L$4:$L$56,MATCH(C13,Settings!$K$4:$K$56,0)),"Unknown")) -> Family & Education | I13: =IF(A13="","",MONTH(A13)) -> 1 | J13: =IF(A13="","",YEAR(A13)) -> 2026 | L13: =IF(OR(B13="",C13=""),"",IF(AND(B13="Income",H13<>"Income"),"Category is not an Income category",IF(AND(B13="Expense",H13="Income"),"Category is an Income category","OK"))) -> OK
A14: 46028 | B14: Expense | C14: Internet / Broadband | D14: Broadband bill | E14: bKash | F14: Link3 | G14: 1000 | H14: =IF(C14="","",IFERROR(INDEX(Settings!$L$4:$L$56,MATCH(C14,Settings!$K$4:$K$56,0)),"Unknown")) -> Housing & Utilities | I14: =IF(A14="","",MONTH(A14)) -> 1 | J14: =IF(A14="","",YEAR(A14)) -> 2026 | L14: =IF(OR(B14="",C14=""),"",IF(AND(B14="Income",H14<>"Income"),"Category is not an Income category",IF(AND(B14="Expense",H14="Income"),"Category is an Income category","OK"))) -> OK
A15: 46029 | B15: Expense | C15: Rickshaw / CNG / Ride-share | D15: Uber / Pathao rides | E15: bKash | F15: Pathao | G15: 940 | H15: =IF(C15="","",IFERROR(INDEX(Settings!$L$4:$L$56,MATCH(C15,Settings!$K$4:$K$56,0)),"Unknown")) -> Transport | I15: =IF(A15="","",MONTH(A15)) -> 1 | J15: =IF(A15="","",YEAR(A15)) -> 2026 | L15: =IF(OR(B15="",C15=""),"",IF(AND(B15="Income",H15<>"Income"),"Category is not an Income category",IF(AND(B15="Expense",H15="Income"),"Category is an Income category","OK"))) -> OK
A16: 46030 | B16: Expense | C16: Electricity (DESCO / DPDC / REB) | D16: Electricity bill (prepaid recharge) | E16: bKash | F16: DESCO | G16: 2150 | H16: =IF(C16="","",IFERROR(INDEX(Settings!$L$4:$L$56,MATCH(C16,Settings!$K$4:$K$56,0)),"Unknown")) -> Housing & Utilities | I16: =IF(A16="","",MONTH(A16)) -> 1 | J16: =IF(A16="","",YEAR(A16)) -> 2026 | L16: =IF(OR(B16="",C16=""),"",IF(AND(B16="Income",H16<>"Income"),"Category is not an Income category",IF(AND(B16="Expense",H16="Income"),"Category is an Income category","OK"))) -> OK
A17: 46031 | B17: Expense | C17: Mobile Recharge & Data | D17: Mobile recharge / data pack | E17: bKash | F17: Grameenphone | G17: 700 | H17: =IF(C17="","",IFERROR(INDEX(Settings!$L$4:$L$56,MATCH(C17,Settings!$K$4:$K$56,0)),"Unknown")) -> Housing & Utilities | I17: =IF(A17="","",MONTH(A17)) -> 1 | J17: =IF(A17="","",YEAR(A17)) -> 2026 | L17: =IF(OR(B17="",C17=""),"",IF(AND(B17="Income",H17<>"Income"),"Category is not an Income category",IF(AND(B17="Expense",H17="Income"),"Category is an Income category","OK"))) -> OK
... A305: 46315 | B305: Expense | C305: Personal Care & Salon | D305: Haircut & grooming | E305: Cash | F305: Salon | G305: 780 | H305: =IF(C305="","",IFERROR(INDEX(Settings!$L$4:$L$56,MATCH(C305,Settings!$K$4:$K$56,0)),"Unknown")) -> Lifestyle | I305: =IF(A305="","",MONTH(A305)) -> 10 | J305: =IF(A305="","",YEAR(A305)) -> 2026 | L305: =IF(OR(B305="",C305=""),"",IF(AND(B305="Income",H305<>"Income"),"Category is not an Income category",IF(AND(B305="Expense",H305="Income"),"Category is an Income category","OK"))) -> OK
H306: =IF(C306="","",IFERROR(INDEX(Settings!$L$4:$L$56,MATCH(C306,Settings!$K$4:$K$56,0)),"Unknown")) | I306: =IF(A306="","",MONTH(A306)) | J306: =IF(A306="","",YEAR(A306)) | L306: =IF(OR(B306="",C306=""),"",IF(AND(B306="Income",H306<>"Income"),"Category is not an Income category",IF(AND(B306="Expense",H306="Income"),"Category is an Income category","OK")))
H307: =IF(C307="","",IFERROR(INDEX(Settings!$L$4:$L$56,MATCH(C307,Settings!$K$4:$K$56,0)),"Unknown")) | I307: =IF(A307="","",MONTH(A307)) | J307: =IF(A307="","",YEAR(A307)) | L307: =IF(OR(B307="",C307=""),"",IF(AND(B307="Income",H307<>"Income"),"Category is not an Income category",IF(AND(B307="Expense",H307="Income"),"Category is an Income category","OK")))
H308: =IF(C308="","",IFERROR(INDEX(Settings!$L$4:$L$56,MATCH(C308,Settings!$K$4:$K$56,0)),"Unknown")) | I308: =IF(A308="","",MONTH(A308)) | J308: =IF(A308="","",YEAR(A308)) | L308: =IF(OR(B308="",C308=""),"",IF(AND(B308="Income",H308<>"Income"),"Category is not an Income category",IF(AND(B308="Expense",H308="Income"),"Category is an Income category","OK")))
H309: =IF(C309="","",IFERROR(INDEX(Settings!$L$4:$L$56,MATCH(C309,Settings!$K$4:$K$56,0)),"Unknown")) | I309: =IF(A309="","",MONTH(A309)) | J309: =IF(A309="","",YEAR(A309)) | L309: =IF(OR(B309="",C309=""),"",IF(AND(B309="Income",H309<>"Income"),"Category is not an Income category",IF(AND(B309="Expense",H309="Income"),"Category is an Income category","OK")))
H310: =IF(C310="","",IFERROR(INDEX(Settings!$L$4:$L$56,MATCH(C310,Settings!$K$4:$K$56,0)),"Unknown")) | I310: =IF(A310="","",MONTH(A310)) | J310: =IF(A310="","",YEAR(A310)) | L310: =IF(OR(B310="",C310=""),"",IF(AND(B310="Income",H310<>"Income"),"Category is not an Income category",IF(AND(B310="Expense",H310="Income"),"Category is an Income category","OK")))
H311: =IF(C311="","",IFERROR(INDEX(Settings!$L$4:$L$56,MATCH(C311,Settings!$K$4:$K$56,0)),"Unknown")) | I311: =IF(A311="","",MONTH(A311)) | J311: =IF(A311="","",YEAR(A311)) | L311: =IF(OR(B311="",C311=""),"",IF(AND(B311="Income",H311<>"Income"),"Category is not an Income category",IF(AND(B311="Expense",H311="Income"),"Category is an Income category","OK")))
H312: =IF(C312="","",IFERROR(INDEX(Settings!$L$4:$L$56,MATCH(C312,Settings!$K$4:$K$56,0)),"Unknown")) | I312: =IF(A312="","",MONTH(A312)) | J312: =IF(A312="","",YEAR(A312)) | L312: =IF(OR(B312="",C312=""),"",IF(AND(B312="Income",H312<>"Income"),"Category is not an Income category",IF(AND(B312="Expense",H312="Income"),"Category is an Income category","OK")))
H313: =IF(C313="","",IFERROR(INDEX(Settings!$L$4:$L$56,MATCH(C313,Settings!$K$4:$K$56,0)),"Unknown")) | I313: =IF(A313="","",MONTH(A313)) | J313: =IF(A313="","",YEAR(A313)) | L313: =IF(OR(B313="",C313=""),"",IF(AND(B313="Income",H313<>"Income"),"Category is not an Income category",IF(AND(B313="Expense",H313="Income"),"Category is an Income category","OK")))
H314: =IF(C314="","",IFERROR(INDEX(Settings!$L$4:$L$56,MATCH(C314,Settings!$K$4:$K$56,0)),"Unknown")) | I314: =IF(A314="","",MONTH(A314)) | J314: =IF(A314="","",YEAR(A314)) | L314: =IF(OR(B314="",C314=""),"",IF(AND(B314="Income",H314<>"Income"),"Category is not an Income category",IF(AND(B314="Expense",H314="Income"),"Category is an Income category","OK")))
H315: =IF(C315="","",IFERROR(INDEX(Settings!$L$4:$L$56,MATCH(C315,Settings!$K$4:$K$56,0)),"Unknown")) | I315: =IF(A315="","",MONTH(A315)) | J315: =IF(A315="","",YEAR(A315)) | L315: =IF(OR(B315="",C315=""),"",IF(AND(B315="Income",H315<>"Income"),"Category is not an Income category",IF(AND(B315="Expense",H315="Income"),"Category is an Income category","OK")))
H316: =IF(C316="","",IFERROR(INDEX(Settings!$L$4:$L$56,MATCH(C316,Settings!$K$4:$K$56,0)),"Unknown")) | I316: =IF(A316="","",MONTH(A316)) | J316: =IF(A316="","",YEAR(A316)) | L316: =IF(OR(B316="",C316=""),"",IF(AND(B316="Income",H316<>"Income"),"Category is not an Income category",IF(AND(B316="Expense",H316="Income"),"Category is an Income category","OK")))
H317: =IF(C317="","",IFERROR(INDEX(Settings!$L$4:$L$56,MATCH(C317,Settings!$K$4:$K$56,0)),"Unknown")) | I317: =IF(A317="","",MONTH(A317)) | J317: =IF(A317="","",YEAR(A317)) | L317: =IF(OR(B317="",C317=""),"",IF(AND(B317="Income",H317<>"Income"),"Category is not an Income category",IF(AND(B317="Expense",H317="Income"),"Category is an Income category","OK")))
... H2005: =IF(C2005="","",IFERROR(INDEX(Settings!$L$4:$L$56,MATCH(C2005,Settings!$K$4:$K$56,0)),"Unknown")) | I2005: =IF(A2005="","",MONTH(A2005)) | J2005: =IF(A2005="","",YEAR(A2005)) | L2005: =IF(OR(B2005="",C2005=""),"",IF(AND(B2005="Income",H2005<>"Income"),"Category is not an Income category",IF(AND(B2005="Expense",H2005="Income"),"Category is an Income category","OK")))

Sheet Budget
A1: BUDGET vs ACTUAL | বাজেট
A2: Enter your planned monthly amount per category (blue). Actuals come from the Transaction Log for the month picked on the Dashboard.
A3: Selected month (change on Dashboard) | B3: =Dashboard!$D$4 -> February
A5: Category | B5: Group | C5: Budget Type | D5: Monthly Budget (BDT) | E5: Actual - Selected Month | F5: Variance (Budget - Actual) | G5: % Used | H5: Status | I5: Annual Budget | J5: YTD Budget | K5: YTD Actual | L5: YTD Variance | M5: Rank key (helper)
A6: =Settings!$K$16 -> House Rent | B6: =Settings!$L$16 -> Housing & Utilities | C6: =Settings!$M$16 -> Needs | D6: 22000 | E6: =INDEX('Annual Matrix'!$C21:$N21,Settings!$B$11) -> 22000 | F6: =D6-E6 -> 0 | G6: =IF(D6=0,"",E6/D6) -> 1 | H6: =IF(D6=0,IF(E6>0,"Unbudgeted","-"),IF(E6>D6,"OVER",IF(E6>=0.9*D6,"WATCH","OK"))) -> WATCH | I6: =D6*12 -> 264000 | J6: =D6*Settings!$B$11 -> 44000 | K6: ='Annual Matrix'!$O21 -> 220000 | L6: =J6-K6 -> -176000 | M6: =E6+ROW()/1000000 -> 22000
A7: =Settings!$K$17 -> Electricity (DESCO / DPDC / REB) | B7: =Settings!$L$17 -> Housing & Utilities | C7: =Settings!$M$17 -> Needs | D7: 3000 | E7: =INDEX('Annual Matrix'!$C22:$N22,Settings!$B$11) -> 1930 | F7: =D7-E7 -> 1070 | G7: =IF(D7=0,"",E7/D7) -> 0.64333333 | H7: =IF(D7=0,IF(E7>0,"Unbudgeted","-"),IF(E7>D7,"OVER",IF(E7>=0.9*D7,"WATCH","OK"))) -> OK | I7: =D7*12 -> 36000 | J7: =D7*Settings!$B$11 -> 6000 | K7: ='Annual Matrix'!$O22 -> 29640 | L7: =J7-K7 -> -23640 | M7: =E7+ROW()/1000000 -> 1930
A8: =Settings!$K$18 -> Gas (Titas / Bakhrabad / Jalalabad) | B8: =Settings!$L$18 -> Housing & Utilities | C8: =Settings!$M$18 -> Needs | D8: 1080 | E8: =INDEX('Annual Matrix'!$C23:$N23,Settings!$B$11) -> 1080 | F8: =D8-E8 -> 0 | G8: =IF(D8=0,"",E8/D8) -> 1 | H8: =IF(D8=0,IF(E8>0,"Unbudgeted","-"),IF(E8>D8,"OVER",IF(E8>=0.9*D8,"WATCH","OK"))) -> WATCH | I8: =D8*12 -> 12960 | J8: =D8*Settings!$B$11 -> 2160 | K8: ='Annual Matrix'!$O23 -> 10800 | L8: =J8-K8 -> -8640 | M8: =E8+ROW()/1000000 -> 1080
A9: =Settings!$K$19 -> Water & Sewerage (WASA) | B9: =Settings!$L$19 -> Housing & Utilities | C9: =Settings!$M$19 -> Needs | D9: 900 | E9: =INDEX('Annual Matrix'!$C24:$N24,Settings!$B$11) -> 900 | F9: =D9-E9 -> 0 | G9: =IF(D9=0,"",E9/D9) -> 1 | H9: =IF(D9=0,IF(E9>0,"Unbudgeted","-"),IF(E9>D9,"OVER",IF(E9>=0.9*D9,"WATCH","OK"))) -> WATCH | I9: =D9*12 -> 10800 | J9: =D9*Settings!$B$11 -> 1800 | K9: ='Annual Matrix'!$O24 -> 9000 | L9: =J9-K9 -> -7200 | M9: =E9+ROW()/1000000 -> 900.00001
A10: =Settings!$K$20 -> Internet / Broadband | B10: =Settings!$L$20 -> Housing & Utilities | C10: =Settings!$M$20 -> Needs | D10: 1000 | E10: =INDEX('Annual Matrix'!$C25:$N25,Settings!$B$11) -> 1000 | F10: =D10-E10 -> 0 | G10: =IF(D10=0,"",E10/D10) -> 1 | H10: =IF(D10=0,IF(E10>0,"Unbudgeted","-"),IF(E10>D10,"OVER",IF(E10>=0.9*D10,"WATCH","OK"))) -> WATCH | I10: =D10*12 -> 12000 | J10: =D10*Settings!$B$11 -> 2000 | K10: ='Annual Matrix'!$O25 -> 10000 | L10: =J10-K10 -> -8000 | M10: =E10+ROW()/1000000 -> 1000
A11: =Settings!$K$21 -> Mobile Recharge & Data | B11: =Settings!$L$21 -> Housing & Utilities | C11: =Settings!$M$21 -> Needs | D11: 700 | E11: =INDEX('Annual Matrix'!$C26:$N26,Settings!$B$11) -> 700 | F11: =D11-E11 -> 0 | G11: =IF(D11=0,"",E11/D11) -> 1 | H11: =IF(D11=0,IF(E11>0,"Unbudgeted","-"),IF(E11>D11,"OVER",IF(E11>=0.9*D11,"WATCH","OK"))) -> WATCH | I11: =D11*12 -> 8400 | J11: =D11*Settings!$B$11 -> 1400 | K11: ='Annual Matrix'!$O26 -> 7000 | L11: =J11-K11 -> -5600 | M11: =E11+ROW()/1000000 -> 700.00001
A12: =Settings!$K$22 -> Maid / Domestic Help | B12: =Settings!$L$22 -> Housing & Utilities | C12: =Settings!$M$22 -> Needs | D12: 3000 | E12: =INDEX('Annual Matrix'!$C27:$N27,Settings!$B$11) -> 3000 | F12: =D12-E12 -> 0 | G12: =IF(D12=0,"",E12/D12) -> 1 | H12: =IF(D12=0,IF(E12>0,"Unbudgeted","-"),IF(E12>D12,"OVER",IF(E12>=0.9*D12,"WATCH","OK"))) -> WATCH | I12: =D12*12 -> 36000 | J12: =D12*Settings!$B$11 -> 6000 | K12: ='Annual Matrix'!$O27 -> 30000 | L12: =J12-K12 -> -24000 | M12: =E12+ROW()/1000000 -> 3000
A13: =Settings!$K$23 -> Home Repair & Maintenance | B13: =Settings!$L$23 -> Housing & Utilities | C13: =Settings!$M$23 -> Needs | D13: 500 | E13: =INDEX('Annual Matrix'!$C28:$N28,Settings!$B$11) -> 0 | F13: =D13-E13 -> 500 | G13: =IF(D13=0,"",E13/D13) -> 0 | H13: =IF(D13=0,IF(E13>0,"Unbudgeted","-"),IF(E13>D13,"OVER",IF(E13>=0.9*D13,"WATCH","OK"))) -> OK | I13: =D13*12 -> 6000 | J13: =D13*Settings!$B$11 -> 1000 | K13: ='Annual Matrix'!$O28 -> 0 | L13: =J13-K13 -> 1000 | M13: =E13+ROW()/1000000 -> 1.3e-05
A14: =Settings!$K$24 -> Service Charge & Holding Tax | B14: =Settings!$L$24 -> Housing & Utilities | C14: =Settings!$M$24 -> Needs | D14: 0 | E14: =INDEX('Annual Matrix'!$C29:$N29,Settings!$B$11) -> 0 | F14: =D14-E14 -> 0 | G14: =IF(D14=0,"",E14/D14) | H14: =IF(D14=0,IF(E14>0,"Unbudgeted","-"),IF(E14>D14,"OVER",IF(E14>=0.9*D14,"WATCH","OK"))) -> - | I14: =D14*12 -> 0 | J14: =D14*Settings!$B$11 -> 0 | K14: ='Annual Matrix'!$O29 -> 0 | L14: =J14-K14 -> 0 | M14: =E14+ROW()/1000000 -> 1.4e-05
A15: =Settings!$K$25 -> Groceries & Bazar | B15: =Settings!$L$25 -> Food | C15: =Settings!$M$25 -> Needs | D15: 11000 | E15: =INDEX('Annual Matrix'!$C30:$N30,Settings!$B$11) -> 11610 | F15: =D15-E15 -> -610 | G15: =IF(D15=0,"",E15/D15) -> 1.0554545 | H15: =IF(D15=0,IF(E15>0,"Unbudgeted","-"),IF(E15>D15,"OVER",IF(E15>=0.9*D15,"WATCH","OK"))) -> OVER | I15: =D15*12 -> 132000 | J15: =D15*Settings!$B$11 -> 22000 | K15: ='Annual Matrix'!$O30 -> 108460 | L15: =J15-K15 -> -86460 | M15: =E15+ROW()/1000000 -> 11610
A16: =Settings!$K$26 -> Dining Out & Food Delivery | B16: =Settings!$L$26 -> Food | C16: =Settings!$M$26 -> Wants | D16: 2000 | E16: =INDEX('Annual Matrix'!$C31:$N31,Settings!$B$11) -> 1060 | F16: =D16-E16 -> 940 | G16: =IF(D16=0,"",E16/D16) -> 0.53 | H16: =IF(D16=0,IF(E16>0,"Unbudgeted","-"),IF(E16>D16,"OVER",IF(E16>=0.9*D16,"WATCH","OK"))) -> OK | I16: =D16*12 -> 24000 | J16: =D16*Settings!$B$11 -> 4000 | K16: ='Annual Matrix'!$O31 -> 10040 | L16: =J16-K16 -> -6040 | M16: =E16+ROW()/1000000 -> 1060
A17: =Settings!$K$27 -> Rickshaw / CNG / Ride-share | B17: =Settings!$L$27 -> Transport | C17: =Settings!$M$27 -> Needs | D17: 2500 | E17: =INDEX('Annual Matrix'!$C32:$N32,Settings!$B$11) -> 1800 | F17: =D17-E17 -> 700 | G17: =IF(D17=0,"",E17/D17) -> 0.72 | H17: =IF(D17=0,IF(E17>0,"Unbudgeted","-"),IF(E17>D17,"OVER",IF(E17>=0.9*D17,"WATCH","OK"))) -> OK | I17: =D17*12 -> 30000 | J17: =D17*Settings!$B$11 -> 5000 | K17: ='Annual Matrix'!$O32 -> 17130 | L17: =J17-K17 -> -12130 | M17: =E17+ROW()/1000000 -> 1800
A18: =Settings!$K$28 -> Bus / Metro Rail / Train | B18: =Settings!$L$28 -> Transport | C18: =Settings!$M$28 -> Needs | D18: 500 | E18: =INDEX('Annual Matrix'!$C33:$N33,Settings!$B$11) -> 0 | F18: =D18-E18 -> 500 | G18: =IF(D18=0,"",E18/D18) -> 0 | H18: =IF(D18=0,IF(E18>0,"Unbudgeted","-"),IF(E18>D18,"OVER",IF(E18>=0.9*D18,"WATCH","OK"))) -> OK | I18: =D18*12 -> 6000 | J18: =D18*Settings!$B$11 -> 1000 | K18: ='Annual Matrix'!$O33 -> 0 | L18: =J18-K18 -> 1000 | M18: =E18+ROW()/1000000 -> 1.8e-05
A19: =Settings!$K$29 -> Fuel (Octane / Petrol / CNG) | B19: =Settings!$L$29 -> Transport | C19: =Settings!$M$29 -> Needs | D19: 1500 | E19: =INDEX('Annual Matrix'!$C34:$N34,Settings!$B$11) -> 1290 | F19: =D19-E19 -> 210 | G19: =IF(D19=0,"",E19/D19) -> 0.86 | H19: =IF(D19=0,IF(E19>0,"Unbudgeted","-"),IF(E19>D19,"OVER",IF(E19>=0.9*D19,"WATCH","OK"))) -> OK | I19: =D19*12 -> 18000 | J19: =D19*Settings!$B$11 -> 3000 | K19: ='Annual Matrix'!$O34 -> 13760 | L19: =J19-K19 -> -10760 | M19: =E19+ROW()/1000000 -> 1290
A20: =Settings!$K$30 -> Vehicle Maintenance & Parking | B20: =Settings!$L$30 -> Transport | C20: =Settings!$M$30 -> Needs | D20: 800 | E20: =INDEX('Annual Matrix'!$C35:$N35,Settings!$B$11) -> 0 | F20: =D20-E20 -> 800 | G20: =IF(D20=0,"",E20/D20) -> 0 | H20: =IF(D20=0,IF(E20>0,"Unbudgeted","-"),IF(E20>D20,"OVER",IF(E20>=0.9*D20,"WATCH","OK"))) -> OK | I20: =D20*12 -> 9600 | J20: =D20*Settings!$B$11 -> 1600 | K20: ='Annual Matrix'!$O35 -> 6420 | L20: =J20-K20 -> -4820 | M20: =E20+ROW()/1000000 -> 2e-05
A21: =Settings!$K$31 -> School / College / University Fees | B21: =Settings!$L$31 -> Family & Education | C21: =Settings!$M$31 -> Needs | D21: 3500 | E21: =INDEX('Annual Matrix'!$C36:$N36,Settings!$B$11) -> 3500 | F21: =D21-E21 -> 0 | G21: =IF(D21=0,"",E21/D21) -> 1 | H21: =IF(D21=0,IF(E21>0,"Unbudgeted","-"),IF(E21>D21,"OVER",IF(E21>=0.9*D21,"WATCH","OK"))) -> WATCH | I21: =D21*12 -> 42000 | J21: =D21*Settings!$B$11 -> 7000 | K21: ='Annual Matrix'!$O36 -> 35000 | L21: =J21-K21 -> -28000 | M21: =E21+ROW()/1000000 -> 3500
A22: =Settings!$K$32 -> Coaching & Books | B22: =Settings!$L$32 -> Family & Education | C22: =Settings!$M$32 -> Needs | D22: 0 | E22: =INDEX('Annual Matrix'!$C37:$N37,Settings!$B$11) -> 0 | F22: =D22-E22 -> 0 | G22: =IF(D22=0,"",E22/D22) | H22: =IF(D22=0,IF(E22>0,"Unbudgeted","-"),IF(E22>D22,"OVER",IF(E22>=0.9*D22,"WATCH","OK"))) -> - | I22: =D22*12 -> 0 | J22: =D22*Settings!$B$11 -> 0 | K22: ='Annual Matrix'!$O37 -> 0 | L22: =J22-K22 -> 0 | M22: =E22+ROW()/1000000 -> 2.2e-05
A23: =Settings!$K$33 -> Child Care & Baby Needs | B23: =Settings!$L$33 -> Family & Education | C23: =Settings!$M$33 -> Needs | D23: 1000 | E23: =INDEX('Annual Matrix'!$C38:$N38,Settings!$B$11) -> 0 | F23: =D23-E23 -> 1000 | G23: =IF(D23=0,"",E23/D23) -> 0 | H23: =IF(D23=0,IF(E23>0,"Unbudgeted","-"),IF(E23>D23,"OVER",IF(E23>=0.9*D23,"WATCH","OK"))) -> OK | I23: =D23*12 -> 12000 | J23: =D23*Settings!$B$11 -> 2000 | K23: ='Annual Matrix'!$O38 -> 0 | L23: =J23-K23 -> 2000 | M23: =E23+ROW()/1000000 -> 2.3e-05
A24: =Settings!$K$34 -> Parents / Family Support | B24: =Settings!$L$34 -> Family & Education | C24: =Settings!$M$34 -> Needs | D24: 5000 | E24: =INDEX('Annual Matrix'!$C39:$N39,Settings!$B$11) -> 5000 | F24: =D24-E24 -> 0 | G24: =IF(D24=0,"",E24/D24) -> 1 | H24: =IF(D24=0,IF(E24>0,"Unbudgeted","-"),IF(E24>D24,"OVER",IF(E24>=0.9*D24,"WATCH","OK"))) -> WATCH | I24: =D24*12 -> 60000 | J24: =D24*Settings!$B$11 -> 10000 | K24: ='Annual Matrix'!$O39 -> 50000 | L24: =J24-K24 -> -40000 | M24: =E24+ROW()/1000000 -> 5000
A25: =Settings!$K$35 -> Medicine & Doctor Visits | B25: =Settings!$L$35 -> Health | C25: =Settings!$M$35 -> Needs | D25: 1500 | E25: =INDEX('Annual Matrix'!$C40:$N40,Settings!$B$11) -> 1770 | F25: =D25-E25 -> -270 | G25: =IF(D25=0,"",E25/D25) -> 1.18 | H25: =IF(D25=0,IF(E25>0,"Unbudgeted","-"),IF(E25>D25,"OVER",IF(E25>=0.9*D25,"WATCH","OK"))) -> OVER | I25: =D25*12 -> 18000 | J25: =D25*Settings!$B$11 -> 3000 | K25: ='Annual Matrix'!$O40 -> 14170 | L25: =J25-K25 -> -11170 | M25: =E25+ROW()/1000000 -> 1770
A26: =Settings!$K$36 -> Medical Tests & Hospital | B26: =Settings!$L$36 -> Health | C26: =Settings!$M$36 -> Needs | D26: 500 | E26: =INDEX('Annual Matrix'!$C41:$N41,Settings!$B$11) -> 0 | F26: =D26-E26 -> 500 | G26: =IF(D26=0,"",E26/D26) -> 0 | H26: =IF(D26=0,IF(E26>0,"Unbudgeted","-"),IF(E26>D26,"OVER",IF(E26>=0.9*D26,"WATCH","OK"))) -> OK | I26: =D26*12 -> 6000 | J26: =D26*Settings!$B$11 -> 1000 | K26: ='Annual Matrix'!$O41 -> 3600 | L26: =J26-K26 -> -2600 | M26: =E26+ROW()/1000000 -> 2.6e-05
A27: =Settings!$K$37 -> Clothing & Footwear | B27: =Settings!$L$37 -> Lifestyle | C27: =Settings!$M$37 -> Wants | D27: 2000 | E27: =INDEX('Annual Matrix'!$C42:$N42,Settings!$B$11) -> 0 | F27: =D27-E27 -> 2000 | G27: =IF(D27=0,"",E27/D27) -> 0 | H27: =IF(D27=0,IF(E27>0,"Unbudgeted","-"),IF(E27>D27,"OVER",IF(E27>=0.9*D27,"WATCH","OK"))) -> OK | I27: =D27*12 -> 24000 | J27: =D27*Settings!$B$11 -> 4000 | K27: ='Annual Matrix'!$O42 -> 22000 | L27: =J27-K27 -> -18000 | M27: =E27+ROW()/1000000 -> 2.7e-05
A28: =Settings!$K$38 -> Personal Care & Salon | B28: =Settings!$L$38 -> Lifestyle | C28: =Settings!$M$38 -> Wants | D28: 800 | E28: =INDEX('Annual Matrix'!$C43:$N43,Settings!$B$11) -> 760 | F28: =D28-E28 -> 40 | G28: =IF(D28=0,"",E28/D28) -> 0.95 | H28: =IF(D28=0,IF(E28>0,"Unbudgeted","-"),IF(E28>D28,"OVER",IF(E28>=0.9*D28,"WATCH","OK"))) -> WATCH | I28: =D28*12 -> 9600 | J28: =D28*Settings!$B$11 -> 1600 | K28: ='Annual Matrix'!$O43 -> 7840 | L28: =J28-K28 -> -6240 | M28: =E28+ROW()/1000000 -> 760.00003
A29: =Settings!$K$39 -> Entertainment & Subscriptions | B29: =Settings!$L$39 -> Lifestyle | C29: =Settings!$M$39 -> Wants | D29: 1100 | E29: =INDEX('Annual Matrix'!$C44:$N44,Settings!$B$11) -> 1100 | F29: =D29-E29 -> 0 | G29: =IF(D29=0,"",E29/D29) -> 1 | H29: =IF(D29=0,IF(E29>0,"Unbudgeted","-"),IF(E29>D29,"OVER",IF(E29>=0.9*D29,"WATCH","OK"))) -> WATCH | I29: =D29*12 -> 13200 | J29: =D29*Settings!$B$11 -> 2200 | K29: ='Annual Matrix'!$O44 -> 11000 | L29: =J29-K29 -> -8800 | M29: =E29+ROW()/1000000 -> 1100
A30: =Settings!$K$40 -> Travel & Holidays | B30: =Settings!$L$40 -> Lifestyle | C30: =Settings!$M$40 -> Wants | D30: 2000 | E30: =INDEX('Annual Matrix'!$C45:$N45,Settings!$B$11) -> 12000 | F30: =D30-E30 -> -10000 | G30: =IF(D30=0,"",E30/D30) -> 6 | H30: =IF(D30=0,IF(E30>0,"Unbudgeted","-"),IF(E30>D30,"OVER",IF(E30>=0.9*D30,"WATCH","OK"))) -> OVER | I30: =D30*12 -> 24000 | J30: =D30*Settings!$B$11 -> 4000 | K30: ='Annual Matrix'!$O45 -> 21000 | L30: =J30-K30 -> -17000 | M30: =E30+ROW()/1000000 -> 12000
A31: =Settings!$K$41 -> Gifts & Social Events | B31: =Settings!$L$41 -> Lifestyle | C31: =Settings!$M$41 -> Wants | D31: 1000 | E31: =INDEX('Annual Matrix'!$C46:$N46,Settings!$B$11) -> 1690 | F31: =D31-E31 -> -690 | G31: =IF(D31=0,"",E31/D31) -> 1.69 | H31: =IF(D31=0,IF(E31>0,"Unbudgeted","-"),IF(E31>D31,"OVER",IF(E31>=0.9*D31,"WATCH","OK"))) -> OVER | I31: =D31*12 -> 12000 | J31: =D31*Settings!$B$11 -> 2000 | K31: ='Annual Matrix'!$O46 -> 7690 | L31: =J31-K31 -> -5690 | M31: =E31+ROW()/1000000 -> 1690
A32: =Settings!$K$42 -> Zakat, Fitra & Sadaqah | B32: =Settings!$L$42 -> Religious & Social | C32: =Settings!$M$42 -> Needs | D32: 3000 | E32: =INDEX('Annual Matrix'!$C47:$N47,Settings!$B$11) -> 0 | F32: =D32-E32 -> 3000 | G32: =IF(D32=0,"",E32/D32) -> 0 | H32: =IF(D32=0,IF(E32>0,"Unbudgeted","-"),IF(E32>D32,"OVER",IF(E32>=0.9*D32,"WATCH","OK"))) -> OK | I32: =D32*12 -> 36000 | J32: =D32*Settings!$B$11 -> 6000 | K32: ='Annual Matrix'!$O47 -> 36650 | L32: =J32-K32 -> -30650 | M32: =E32+ROW()/1000000 -> 3.2e-05
A33: =Settings!$K$43 -> Qurbani (Eid-ul-Adha) | B33: =Settings!$L$43 -> Religious & Social | C33: =Settings!$M$43 -> Wants | D33: 1500 | E33: =INDEX('Annual Matrix'!$C48:$N48,Settings!$B$11) -> 0 | F33: =D33-E33 -> 1500 | G33: =IF(D33=0,"",E33/D33) -> 0 | H33: =IF(D33=0,IF(E33>0,"Unbudgeted","-"),IF(E33>D33,"OVER",IF(E33>=0.9*D33,"WATCH","OK"))) -> OK | I33: =D33*12 -> 18000 | J33: =D33*Settings!$B$11 -> 3000 | K33: ='Annual Matrix'!$O48 -> 20000 | L33: =J33-K33 -> -17000 | M33: =E33+ROW()/1000000 -> 3.3e-05
A34: =Settings!$K$44 -> Festival Expenses (Eid / Puja / Boishakh) | B34: =Settings!$L$44 -> Religious & Social | C34: =Settings!$M$44 -> Wants | D34: 1000 | E34: =INDEX('Annual Matrix'!$C49:$N49,Settings!$B$11) -> 0 | F34: =D34-E34 -> 1000 | G34: =IF(D34=0,"",E34/D34) -> 0 | H34: =IF(D34=0,IF(E34>0,"Unbudgeted","-"),IF(E34>D34,"OVER",IF(E34>=0.9*D34,"WATCH","OK"))) -> OK | I34: =D34*12 -> 12000 | J34: =D34*Settings!$B$11 -> 2000 | K34: ='Annual Matrix'!$O49 -> 18500 | L34: =J34-K34 -> -16500 | M34: =E34+ROW()/1000000 -> 3.4e-05
A35: =Settings!$K$45 -> Loan EMI | B35: =Settings!$L$45 -> Financial Obligations | C35: =Settings!$M$45 -> Needs | D35: 15300 | E35: =INDEX('Annual Matrix'!$C50:$N50,Settings!$B$11) -> 15300 | F35: =D35-E35 -> 0 | G35: =IF(D35=0,"",E35/D35) -> 1 | H35: =IF(D35=0,IF(E35>0,"Unbudgeted","-"),IF(E35>D35,"OVER",IF(E35>=0.9*D35,"WATCH","OK"))) -> WATCH | I35: =D35*12 -> 183600 | J35: =D35*Settings!$B$11 -> 30600 | K35: ='Annual Matrix'!$O50 -> 153000 | L35: =J35-K35 -> -122400 | M35: =E35+ROW()/1000000 -> 15300
A36: =Settings!$K$46 -> Credit Card Payment | B36: =Settings!$L$46 -> Financial Obligations | C36: =Settings!$M$46 -> Needs | D36: 2800 | E36: =INDEX('Annual Matrix'!$C51:$N51,Settings!$B$11) -> 2800 | F36: =D36-E36 -> 0 | G36: =IF(D36=0,"",E36/D36) -> 1 | H36: =IF(D36=0,IF(E36>0,"Unbudgeted","-"),IF(E36>D36,"OVER",IF(E36>=0.9*D36,"WATCH","OK"))) -> WATCH | I36: =D36*12 -> 33600 | J36: =D36*Settings!$B$11 -> 5600 | K36: ='Annual Matrix'!$O51 -> 25200 | L36: =J36-K36 -> -19600 | M36: =E36+ROW()/1000000 -> 2800
A37: =Settings!$K$47 -> Insurance Premium | B37: =Settings!$L$47 -> Financial Obligations | C37: =Settings!$M$47 -> Needs | D37: 2500 | E37: =INDEX('Annual Matrix'!$C52:$N52,Settings!$B$11) -> 2500 | F37: =D37-E37 -> 0 | G37: =IF(D37=0,"",E37/D37) -> 1 | H37: =IF(D37=0,IF(E37>0,"Unbudgeted","-"),IF(E37>D37,"OVER",IF(E37>=0.9*D37,"WATCH","OK"))) -> WATCH | I37: =D37*12 -> 30000 | J37: =D37*Settings!$B$11 -> 5000 | K37: ='Annual Matrix'!$O52 -> 25000 | L37: =J37-K37 -> -20000 | M37: =E37+ROW()/1000000 -> 2500
A38: =Settings!$K$48 -> Income Tax & Govt Fees | B38: =Settings!$L$48 -> Financial Obligations | C38: =Settings!$M$48 -> Needs | D38: 500 | E38: =INDEX('Annual Matrix'!$C53:$N53,Settings!$B$11) -> 1200 | F38: =D38-E38 -> -700 | G38: =IF(D38=0,"",E38/D38) -> 2.4 | H38: =IF(D38=0,IF(E38>0,"Unbudgeted","-"),IF(E38>D38,"OVER",IF(E38>=0.9*D38,"WATCH","OK"))) -> OVER | I38: =D38*12 -> 6000 | J38: =D38*Settings!$B$11 -> 1000 | K38: ='Annual Matrix'!$O53 -> 6200 | L38: =J38-K38 -> -5200 | M38: =E38+ROW()/1000000 -> 1200
A39: =Settings!$K$49 -> Bank / MFS Charges | B39: =Settings!$L$49 -> Financial Obligations | C39: =Settings!$M$49 -> Needs | D39: 250 | E39: =INDEX('Annual Matrix'!$C54:$N54,Settings!$B$11) -> 250 | F39: =D39-E39 -> 0 | G39: =IF(D39=0,"",E39/D39) -> 1 | H39: =IF(D39=0,IF(E39>0,"Unbudgeted","-"),IF(E39>D39,"OVER",IF(E39>=0.9*D39,"WATCH","OK"))) -> WATCH | I39: =D39*12 -> 3000 | J39: =D39*Settings!$B$11 -> 500 | K39: ='Annual Matrix'!$O54 -> 2250 | L39: =J39-K39 -> -1750 | M39: =E39+ROW()/1000000 -> 250.00004
A40: =Settings!$K$50 -> DPS Deposit | B40: =Settings!$L$50 -> Savings & Investments | C40: =Settings!$M$50 -> Savings | D40: 5000 | E40: =INDEX('Annual Matrix'!$C55:$N55,Settings!$B$11) -> 5000 | F40: =D40-E40 -> 0 | G40: =IF(D40=0,"",E40/D40) -> 1 | H40: =IF(D40=0,IF(E40>0,"Unbudgeted","-"),IF(E40>D40,"OVER",IF(E40>=0.9*D40,"WATCH","OK"))) -> WATCH | I40: =D40*12 -> 60000 | J40: =D40*Settings!$B$11 -> 10000 | K40: ='Annual Matrix'!$O55 -> 50000 | L40: =J40-K40 -> -40000 | M40: =E40+ROW()/1000000 -> 5000
A41: =Settings!$K$51 -> FDR / Sanchayapatra Purchase | B41: =Settings!$L$51 -> Savings & Investments | C41: =Settings!$M$51 -> Savings | D41: 0 | E41: =INDEX('Annual Matrix'!$C56:$N56,Settings!$B$11) -> 0 | F41: =D41-E41 -> 0 | G41: =IF(D41=0,"",E41/D41) | H41: =IF(D41=0,IF(E41>0,"Unbudgeted","-"),IF(E41>D41,"OVER",IF(E41>=0.9*D41,"WATCH","OK"))) -> - | I41: =D41*12 -> 0 | J41: =D41*Settings!$B$11 -> 0 | K41: ='Annual Matrix'!$O56 -> 50000 | L41: =J41-K41 -> -50000 | M41: =E41+ROW()/1000000 -> 4.1e-05
...

Sheet Annual Matrix
A1: ANNUAL MATRIX | Category x Month
A2: Fully automatic - sums the Transaction Log by category and month for the tracking year set in Settings. Do not type here.
A3: month # (helper) | C3: 1 | D3: 2 | E3: 3 | F3: 4 | G3: 5 | H3: 6 | I3: 7 | J3: 8 | K3: 9 | L3: 10 | M3: 11 | N3: 12
A4: Category | B4: Group | C4: Jan | D4: Feb | E4: Mar | F4: Apr | G4: May | H4: Jun | I4: Jul | J4: Aug | K4: Sep | L4: Oct | M4: Nov | N4: Dec | O4: YTD Total | P4: Annual Budget | Q4: Budget - Actual | R4: % of Budget Used
A5: INCOME
A6: =Settings!$K$4 -> Salary | B6: Income | C6: =SUMIFS(Transactions!$G$6:$G$2005,Transactions!$B$6:$B$2005,"Income",Transactions!$C$6:$C$2005,$A6,Transactions!$I$6:$I$2005,C$3,Transactions!$J$6:$J$2005,Settings!$B$5) -> 115000 | D6: =SUMIFS(Transactions!$G$6:$G$2005,Transactions!$B$6:$B$2005,"Income",Transactions!$C$6:$C$2005,$A6,Transactions!$I$6:$I$2005,D$3,Transactions!$J$6:$J$2005,Settings!$B$5) -> 115000 | E6: =SUMIFS(Transactions!$G$6:$G$2005,Transactions!$B$6:$B$2005,"Income",Transactions!$C$6:$C$2005,$A6,Transactions!$I$6:$I$2005,E$3,Transactions!$J$6:$J$2005,Settings!$B$5) -> 115000 | F6: =SUMIFS(Transactions!$G$6:$G$2005,Transactions!$B$6:$B$2005,"Income",Transactions!$C$6:$C$2005,$A6,Transactions!$I$6:$I$2005,F$3,Transactions!$J$6:$J$2005,Settings!$B$5) -> 115000 | G6: =SUMIFS(Transactions!$G$6:$G$2005,Transactions!$B$6:$B$2005,"Income",Transactions!$C$6:$C$2005,$A6,Transactions!$I$6:$I$2005,G$3,Transactions!$J$6:$J$2005,Settings!$B$5) -> 115000 | H6: =SUMIFS(Transactions!$G$6:$G$2005,Transactions!$B$6:$B$2005,"Income",Transactions!$C$6:$C$2005,$A6,Transactions!$I$6:$I$2005,H$3,Transactions!$J$6:$J$2005,Settings!$B$5) -> 115000 | I6: =SUMIFS(Transactions!$G$6:$G$2005,Transactions!$B$6:$B$2005,"Income",Transactions!$C$6:$C$2005,$A6,Transactions!$I$6:$I$2005,I$3,Transactions!$J$6:$J$2005,Settings!$B$5) -> 115000 | J6: =SUMIFS(Transactions!$G$6:$G$2005,Transactions!$B$6:$B$2005,"Income",Transactions!$C$6:$C$2005,$A6,Transactions!$I$6:$I$2005,J$3,Transactions!$J$6:$J$2005,Settings!$B$5) -> 115000 | ... N6: =SUMIFS(Transactions!$G$6:$G$2005,Transactions!$B$6:$B$2005,"Income",Transactions!$C$6:$C$2005,$A6,Transactions!$I$6:$I$2005,N$3,Transactions!$J$6:$J$2005,Settings!$B$5) -> 0 | O6: =SUM(C6:N6) -> 1150000
A7: =Settings!$K$5 -> Festival Bonus (Eid) | B7: Income | C7: =SUMIFS(Transactions!$G$6:$G$2005,Transactions!$B$6:$B$2005,"Income",Transactions!$C$6:$C$2005,$A7,Transactions!$I$6:$I$2005,C$3,Transactions!$J$6:$J$2005,Settings!$B$5) -> 0 | D7: =SUMIFS(Transactions!$G$6:$G$2005,Transactions!$B$6:$B$2005,"Income",Transactions!$C$6:$C$2005,$A7,Transactions!$I$6:$I$2005,D$3,Transactions!$J$6:$J$2005,Settings!$B$5) -> 0 | E7: =SUMIFS(Transactions!$G$6:$G$2005,Transactions!$B$6:$B$2005,"Income",Transactions!$C$6:$C$2005,$A7,Transactions!$I$6:$I$2005,E$3,Transactions!$J$6:$J$2005,Settings!$B$5) -> 72000 | F7: =SUMIFS(Transactions!$G$6:$G$2005,Transactions!$B$6:$B$2005,"Income",Transactions!$C$6:$C$2005,$A7,Transactions!$I$6:$I$2005,F$3,Transactions!$J$6:$J$2005,Settings!$B$5) -> 0 | G7: =SUMIFS(Transactions!$G$6:$G$2005,Transactions!$B$6:$B$2005,"Income",Transactions!$C$6:$C$2005,$A7,Transactions!$I$6:$I$2005,G$3,Transactions!$J$6:$J$2005,Settings!$B$5) -> 72000 | H7: =SUMIFS(Transactions!$G$6:$G$2005,Transactions!$B$6:$B$2005,"Income",Transactions!$C$6:$C$2005,$A7,Transactions!$I$6:$I$2005,H$3,Transactions!$J$6:$J$2005,Settings!$B$5) -> 0 | I7: =SUMIFS(Transactions!$G$6:$G$2005,Transactions!$B$6:$B$2005,"Income",Transactions!$C$6:$C$2005,$A7,Transactions!$I$6:$I$2005,I$3,Transactions!$J$6:$J$2005,Settings!$B$5) -> 0 | J7: =SUMIFS(Transactions!$G$6:$G$2005,Transactions!$B$6:$B$2005,"Income",Transactions!$C$6:$C$2005,$A7,Transactions!$I$6:$I$2005,J$3,Transactions!$J$6:$J$2005,Settings!$B$5) -> 0 | ... N7: =SUMIFS(Transactions!$G$6:$G$2005,Transactions!$B$6:$B$2005,"Income",Transactions!$C$6:$C$2005,$A7,Transactions!$I$6:$I$2005,N$3,Transactions!$J$6:$J$2005,Settings!$B$5) -> 0 | O7: =SUM(C7:N7) -> 144000
A8: =Settings!$K$6 -> Business / Trade Income | B8: Income | C8: =SUMIFS(Transactions!$G$6:$G$2005,Transactions!$B$6:$B$2005,"Income",Transactions!$C$6:$C$2005,$A8,Transactions!$I$6:$I$2005,C$3,Transactions!$J$6:$J$2005,Settings!$B$5) -> 0 | D8: =SUMIFS(Transactions!$G$6:$G$2005,Transactions!$B$6:$B$2005,"Income",Transactions!$C$6:$C$2005,$A8,Transactions!$I$6:$I$2005,D$3,Transactions!$J$6:$J$2005,Settings!$B$5) -> 0 | E8: =SUMIFS(Transactions!$G$6:$G$2005,Transactions!$B$6:$B$2005,"Income",Transactions!$C$6:$C$2005,$A8,Transactions!$I$6:$I$2005,E$3,Transactions!$J$6:$J$2005,Settings!$B$5) -> 0 | F8: =SUMIFS(Transactions!$G$6:$G$2005,Transactions!$B$6:$B$2005,"Income",Transactions!$C$6:$C$2005,$A8,Transactions!$I$6:$I$2005,F$3,Transactions!$J$6:$J$2005,Settings!$B$5) -> 0 | G8: =SUMIFS(Transactions!$G$6:$G$2005,Transactions!$B$6:$B$2005,"Income",Transactions!$C$6:$C$2005,$A8,Transactions!$I$6:$I$2005,G$3,Transactions!$J$6:$J$2005,Settings!$B$5) -> 0 | H8: =SUMIFS(Transactions!$G$6:$G$2005,Transactions!$B$6:$B$2005,"Income",Transactions!$C$6:$C$2005,$A8,Transactions!$I$6:$I$2005,H$3,Transactions!$J$6:$J$2005,Settings!$B$5) -> 0 | I8: =SUMIFS(Transactions!$G$6:$G$2005,Transactions!$B$6:$B$2005,"Income",Transactions!$C$6:$C$2005,$A8,Transactions!$I$6:$I$2005,I$3,Transactions!$J$6:$J$2005,Settings!$B$5) -> 0 | J8: =SUMIFS(Transactions!$G$6:$G$2005,Transactions!$B$6:$B$2005,"Income",Transactions!$C$6:$C$2005,$A8,Transactions!$I$6:$I$2005,J$3,Transactions!$J$6:$J$2005,Settings!$B$5) -> 0 | ... N8: =SUMIFS(Transactions!$G$6:$G$2005,Transactions!$B$6:$B$2005,"Income",Transactions!$C$6:$C$2005,$A8,Transactions!$I$6:$I$2005,N$3,Transactions!$J$6:$J$2005,Settings!$B$5) -> 0 | O8: =SUM(C8:N8) -> 0
A9: =Settings!$K$7 -> Freelance / Side Income | B9: Income | C9: =SUMIFS(Transactions!$G$6:$G$2005,Transactions!$B$6:$B$2005,"Income",Transactions!$C$6:$C$2005,$A9,Transactions!$I$6:$I$2005,C$3,Transactions!$J$6:$J$2005,Settings!$B$5) -> 0 | D9: =SUMIFS(Transactions!$G$6:$G$2005,Transactions!$B$6:$B$2005,"Income",Transactions!$C$6:$C$2005,$A9,Transactions!$I$6:$I$2005,D$3,Transactions!$J$6:$J$2005,Settings!$B$5) -> 13330 | E9: =SUMIFS(Transactions!$G$6:$G$2005,Transactions!$B$6:$B$2005,"Income",Transactions!$C$6:$C$2005,$A9,Transactions!$I$6:$I$2005,E$3,Transactions!$J$6:$J$2005,Settings!$B$5) -> 0 | F9: =SUMIFS(Transactions!$G$6:$G$2005,Transactions!$B$6:$B$2005,"Income",Transactions!$C$6:$C$2005,$A9,Transactions!$I$6:$I$2005,F$3,Transactions!$J$6:$J$2005,Settings!$B$5) -> 14480 | G9: =SUMIFS(Transactions!$G$6:$G$2005,Transactions!$B$6:$B$2005,"Income",Transactions!$C$6:$C$2005,$A9,Transactions!$I$6:$I$2005,G$3,Transactions!$J$6:$J$2005,Settings!$B$5) -> 0 | H9: =SUMIFS(Transactions!$G$6:$G$2005,Transactions!$B$6:$B$2005,"Income",Transactions!$C$6:$C$2005,$A9,Transactions!$I$6:$I$2005,H$3,Transactions!$J$6:$J$2005,Settings!$B$5) -> 13120 | I9: =SUMIFS(Transactions!$G$6:$G$2005,Transactions!$B$6:$B$2005,"Income",Transactions!$C$6:$C$2005,$A9,Transactions!$I$6:$I$2005,I$3,Transactions!$J$6:$J$2005,Settings!$B$5) -> 0 | J9: =SUMIFS(Transactions!$G$6:$G$2005,Transactions!$B$6:$B$2005,"Income",Transactions!$C$6:$C$2005,$A9,Transactions!$I$6:$I$2005,J$3,Transactions!$J$6:$J$2005,Settings!$B$5) -> 12840 | ... N9: =SUMIFS(Transactions!$G$6:$G$2005,Transactions!$B$6:$B$2005,"Income",Transactions!$C$6:$C$2005,$A9,Transactions!$I$6:$I$2005,N$3,Transactions!$J$6:$J$2005,Settings!$B$5) -> 0 | O9: =SUM(C9:N9) -> 67170
A10: =Settings!$K$8 -> Remittance (Foreign) | B10: Income | C10: =SUMIFS(Transactions!$G$6:$G$2005,Transactions!$B$6:$B$2005,"Income",Transactions!$C$6:$C$2005,$A10,Transactions!$I$6:$I$2005,C$3,Transactions!$J$6:$J$2005,Settings!$B$5) -> 0 | D10: =SUMIFS(Transactions!$G$6:$G$2005,Transactions!$B$6:$B$2005,"Income",Transactions!$C$6:$C$2005,$A10,Transactions!$I$6:$I$2005,D$3,Transactions!$J$6:$J$2005,Settings!$B$5) -> 0 | E10: =SUMIFS(Transactions!$G$6:$G$2005,Transactions!$B$6:$B$2005,"Income",Transactions!$C$6:$C$2005,$A10,Transactions!$I$6:$I$2005,E$3,Transactions!$J$6:$J$2005,Settings!$B$5) -> 0 | F10: =SUMIFS(Transactions!$G$6:$G$2005,Transactions!$B$6:$B$2005,"Income",Transactions!$C$6:$C$2005,$A10,Transactions!$I$6:$I$2005,F$3,Transactions!$J$6:$J$2005,Settings!$B$5) -> 0 | G10: =SUMIFS(Transactions!$G$6:$G$2005,Transactions!$B$6:$B$2005,"Income",Transactions!$C$6:$C$2005,$A10,Transactions!$I$6:$I$2005,G$3,Transactions!$J$6:$J$2005,Settings!$B$5) -> 0 | H10: =SUMIFS(Transactions!$G$6:$G$2005,Transactions!$B$6:$B$2005,"Income",Transactions!$C$6:$C$2005,$A10,Transactions!$I$6:$I$2005,H$3,Transactions!$J$6:$J$2005,Settings!$B$5) -> 0 | I10: =SUMIFS(Transactions!$G$6:$G$2005,Transactions!$B$6:$B$2005,"Income",Transactions!$C$6:$C$2005,$A10,Transactions!$I$6:$I$2005,I$3,Transactions!$J$6:$J$2005,Settings!$B$5) -> 0 | J10: =SUMIFS(Transactions!$G$6:$G$2005,Transactions!$B$6:$B$2005,"Income",Transactions!$C$6:$C$2005,$A10,Transactions!$I$6:$I$2005,J$3,Transactions!$J$6:$J$2005,Settings!$B$5) -> 0 | ... N10: =SUMIFS(Transactions!$G$6:$G$2005,Transactions!$B$6:$B$2005,"Income",Transactions!$C$6:$C$2005,$A10,Transactions!$I$6:$I$2005,N$3,Transactions!$J$6:$J$2005,Settings!$B$5) -> 0 | O10: =SUM(C10:N10) -> 0
A11: =Settings!$K$9 -> Rental Income | B11: Income | C11: =SUMIFS(Transactions!$G$6:$G$2005,Transactions!$B$6:$B$2005,"Income",Transactions!$C$6:$C$2005,$A11,Transactions!$I$6:$I$2005,C$3,Transactions!$J$6:$J$2005,Settings!$B$5) -> 0 | D11: =SUMIFS(Transactions!$G$6:$G$2005,Transactions!$B$6:$B$2005,"Income",Transactions!$C$6:$C$2005,$A11,Transactions!$I$6:$I$2005,D$3,Transactions!$J$6:$J$2005,Settings!$B$5) -> 0 | E11: =SUMIFS(Transactions!$G$6:$G$2005,Transactions!$B$6:$B$2005,"Income",Transactions!$C$6:$C$2005,$A11,Transactions!$I$6:$I$2005,E$3,Transactions!$J$6:$J$2005,Settings!$B$5) -> 0 | F11: =SUMIFS(Transactions!$G$6:$G$2005,Transactions!$B$6:$B$2005,"Income",Transactions!$C$6:$C$2005,$A11,Transactions!$I$6:$I$2005,F$3,Transactions!$J$6:$J$2005,Settings!$B$5) -> 0 | G11: =SUMIFS(Transactions!$G$6:$G$2005,Transactions!$B$6:$B$2005,"Income",Transactions!$C$6:$C$2005,$A11,Transactions!$I$6:$I$2005,G$3,Transactions!$J$6:$J$2005,Settings!$B$5) -> 0 | H11: =SUMIFS(Transactions!$G$6:$G$2005,Transactions!$B$6:$B$2005,"Income",Transactions!$C$6:$C$2005,$A11,Transactions!$I$6:$I$2005,H$3,Transactions!$J$6:$J$2005,Settings!$B$5) -> 0 | I11: =SUMIFS(Transactions!$G$6:$G$2005,Transactions!$B$6:$B$2005,"Income",Transactions!$C$6:$C$2005,$A11,Transactions!$I$6:$I$2005,I$3,Transactions!$J$6:$J$2005,Settings!$B$5) -> 0 | J11: =SUMIFS(Transactions!$G$6:$G$2005,Transactions!$B$6:$B$2005,"Income",Transactions!$C$6:$C$2005,$A11,Transactions!$I$6:$I$2005,J$3,Transactions!$J$6:$J$2005,Settings!$B$5) -> 0 | ... N11: =SUMIFS(Transactions!$G$6:$G$2005,Transactions!$B$6:$B$2005,"Income",Transactions!$C$6:$C$2005,$A11,Transactions!$I$6:$I$2005,N$3,Transactions!$J$6:$J$2005,Settings!$B$5) -> 0 | O11: =SUM(C11:N11) -> 0
A12: =Settings!$K$10 -> Agricultural Income | B12: Income | C12: =SUMIFS(Transactions!$G$6:$G$2005,Transactions!$B$6:$B$2005,"Income",Transactions!$C$6:$C$2005,$A12,Transactions!$I$6:$I$2005,C$3,Transactions!$J$6:$J$2005,Settings!$B$5) -> 0 | D12: =SUMIFS(Transactions!$G$6:$G$2005,Transactions!$B$6:$B$2005,"Income",Transactions!$C$6:$C$2005,$A12,Transactions!$I$6:$I$2005,D$3,Transactions!$J$6:$J$2005,Settings!$B$5) -> 0 | E12: =SUMIFS(Transactions!$G$6:$G$2005,Transactions!$B$6:$B$2005,"Income",Transactions!$C$6:$C$2005,$A12,Transactions!$I$6:$I$2005,E$3,Transactions!$J$6:$J$2005,Settings!$B$5) -> 0 | F12: =SUMIFS(Transactions!$G$6:$G$2005,Transactions!$B$6:$B$2005,"Income",Transactions!$C$6:$C$2005,$A12,Transactions!$I$6:$I$2005,F$3,Transactions!$J$6:$J$2005,Settings!$B$5) -> 0 | G12: =SUMIFS(Transactions!$G$6:$G$2005,Transactions!$B$6:$B$2005,"Income",Transactions!$C$6:$C$2005,$A12,Transactions!$I$6:$I$2005,G$3,Transactions!$J$6:$J$2005,Settings!$B$5) -> 0 | H12: =SUMIFS(Transactions!$G$6:$G$2005,Transactions!$B$6:$B$2005,"Income",Transactions!$C$6:$C$2005,$A12,Transactions!$I$6:$I$2005,H$3,Transactions!$J$6:$J$2005,Settings!$B$5) -> 0 | I12: =SUMIFS(Transactions!$G$6:$G$2005,Transactions!$B$6:$B$2005,"Income",Transactions!$C$6:$C$2005,$A12,Transactions!$I$6:$I$2005,I$3,Transactions!$J$6:$J$2005,Settings!$B$5) -> 0 | J12: =SUMIFS(Transactions!$G$6:$G$2005,Transactions!$B$6:$B$2005,"Income",Transactions!$C$6:$C$2005,$A12,Transactions!$I$6:$I$2005,J$3,Transactions!$J$6:$J$2005,Settings!$B$5) -> 0 | ... N12: =SUMIFS(Transactions!$G$6:$G$2005,Transactions!$B$6:$B$2005,"Income",Transactions!$C$6:$C$2005,$A12,Transactions!$I$6:$I$2005,N$3,Transactions!$J$6:$J$2005,Settings!$B$5) -> 0 | O12: =SUM(C12:N12) -> 0
A13: =Settings!$K$11 -> Bank Interest | B13: Income | C13: =SUMIFS(Transactions!$G$6:$G$2005,Transactions!$B$6:$B$2005,"Income",Transactions!$C$6:$C$2005,$A13,Transactions!$I$6:$I$2005,C$3,Transactions!$J$6:$J$2005,Settings!$B$5) -> 0 | D13: =SUMIFS(Transactions!$G$6:$G$2005,Transactions!$B$6:$B$2005,"Income",Transactions!$C$6:$C$2005,$A13,Transactions!$I$6:$I$2005,D$3,Transactions!$J$6:$J$2005,Settings!$B$5) -> 0 | E13: =SUMIFS(Transactions!$G$6:$G$2005,Transactions!$B$6:$B$2005,"Income",Transactions!$C$6:$C$2005,$A13,Transactions!$I$6:$I$2005,E$3,Transactions!$J$6:$J$2005,Settings!$B$5) -> 3200 | F13: =SUMIFS(Transactions!$G$6:$G$2005,Transactions!$B$6:$B$2005,"Income",Transactions!$C$6:$C$2005,$A13,Transactions!$I$6:$I$2005,F$3,Transactions!$J$6:$J$2005,Settings!$B$5) -> 0 | G13: =SUMIFS(Transactions!$G$6:$G$2005,Transactions!$B$6:$B$2005,"Income",Transactions!$C$6:$C$2005,$A13,Transactions!$I$6:$I$2005,G$3,Transactions!$J$6:$J$2005,Settings!$B$5) -> 0 | H13: =SUMIFS(Transactions!$G$6:$G$2005,Transactions!$B$6:$B$2005,"Income",Transactions!$C$6:$C$2005,$A13,Transactions!$I$6:$I$2005,H$3,Transactions!$J$6:$J$2005,Settings!$B$5) -> 3200 | I13: =SUMIFS(Transactions!$G$6:$G$2005,Transactions!$B$6:$B$2005,"Income",Transactions!$C$6:$C$2005,$A13,Transactions!$I$6:$I$2005,I$3,Transactions!$J$6:$J$2005,Settings!$B$5) -> 0 | J13: =SUMIFS(Transactions!$G$6:$G$2005,Transactions!$B$6:$B$2005,"Income",Transactions!$C$6:$C$2005,$A13,Transactions!$I$6:$I$2005,J$3,Transactions!$J$6:$J$2005,Settings!$B$5) -> 0 | ... N13: =SUMIFS(Transactions!$G$6:$G$2005,Transactions!$B$6:$B$2005,"Income",Transactions!$C$6:$C$2005,$A13,Transactions!$I$6:$I$2005,N$3,Transactions!$J$6:$J$2005,Settings!$B$5) -> 0 | O13: =SUM(C13:N13) -> 9600
A14: =Settings!$K$12 -> Sanchayapatra Profit | B14: Income | C14: =SUMIFS(Transactions!$G$6:$G$2005,Transactions!$B$6:$B$2005,"Income",Transactions!$C$6:$C$2005,$A14,Transactions!$I$6:$I$2005,C$3,Transactions!$J$6:$J$2005,Settings!$B$5) -> 7776 | D14: =SUMIFS(Transactions!$G$6:$G$2005,Transactions!$B$6:$B$2005,"Income",Transactions!$C$6:$C$2005,$A14,Transactions!$I$6:$I$2005,D$3,Transactions!$J$6:$J$2005,Settings!$B$5) -> 0 | E14: =SUMIFS(Transactions!$G$6:$G$2005,Transactions!$B$6:$B$2005,"Income",Transactions!$C$6:$C$2005,$A14,Transactions!$I$6:$I$2005,E$3,Transactions!$J$6:$J$2005,Settings!$B$5) -> 0 | F14: =SUMIFS(Transactions!$G$6:$G$2005,Transactions!$B$6:$B$2005,"Income",Transactions!$C$6:$C$2005,$A14,Transactions!$I$6:$I$2005,F$3,Transactions!$J$6:$J$2005,Settings!$B$5) -> 7776 | G14: =SUMIFS(Transactions!$G$6:$G$2005,Transactions!$B$6:$B$2005,"Income",Transactions!$C$6:$C$2005,$A14,Transactions!$I$6:$I$2005,G$3,Transactions!$J$6:$J$2005,Settings!$B$5) -> 0 | H14: =SUMIFS(Transactions!$G$6:$G$2005,Transactions!$B$6:$B$2005,"Income",Transactions!$C$6:$C$2005,$A14,Transactions!$I$6:$I$2005,H$3,Transactions!$J$6:$J$2005,Settings!$B$5) -> 0 | I14: =SUMIFS(Transactions!$G$6:$G$2005,Transactions!$B$6:$B$2005,"Income",Transactions!$C$6:$C$2005,$A14,Transactions!$I$6:$I$2005,I$3,Transactions!$J$6:$J$2005,Settings!$B$5) -> 7776 | J14: =SUMIFS(Transactions!$G$6:$G$2005,Transactions!$B$6:$B$2005,"Income",Transactions!$C$6:$C$2005,$A14,Transactions!$I$6:$I$2005,J$3,Transactions!$J$6:$J$2005,Settings!$B$5) -> 0 | ... N14: =SUMIFS(Transactions!$G$6:$G$2005,Transactions!$B$6:$B$2005,"Income",Transactions!$C$6:$C$2005,$A14,Transactions!$I$6:$I$2005,N$3,Transactions!$J$6:$J$2005,Settings!$B$5) -> 0 | O14: =SUM(C14:N14) -> 31104
